Workbook

Sheet 1. 투자 현황(현재)
K2: =TODAY() -> 46176
B4: 구분 | C4: 금액 | D4: 국가 | E4: 코드 | F4: 항목 | G4: 총 수량 | H4: 현재가 (구매시) | J4: 투자금액 | K4: 현재가 | L4: 조회금액 | M4: 수익금액 | N4: 수익율(%)
B5: 퇴직연금 (220-91-xxxx-757) | C5: =IFERROR(__xludf.DUMMYFUNCTION("IMPORTRANGE(""18m7_5Vy-SocSuBMtXmritoiWfMy_VSJ0LqQCfdmFyYU/edit?gid=852545723"",""'1.자산투자(원금)'!q6"")"),113724104) -> 113724104 | D5: 한국 | E5: 442580 | F5: Plus HBM 글로벌 반도체 | G5: 1847 | H5: 111566 | J5: =G5*H5 -> 206062402 | K5: =IFERROR(__xludf.DUMMYFUNCTION("iferror(IF($D5=""한국"",GOOGLEFINANCE($E5),""""),)"),127675) -> 127675 | L5: =$G5*K5 -> 235815725 | M5: =L5-$J5 -> 29753323 | N5: =(L5-$J5)/$J5 -> 0.14438987
D6: 한국 | E6: 0162Z0 | F6: RISE 삼성하이닉스채권 | G6: 6558 | H6: 11558 | J6: =G6*H6 -> 75797364 | K6: =IFERROR(__xludf.DUMMYFUNCTION("INDEX(IMPORTXML(""https://finance.naver.com/item/main.naver?code=0162Z0"",""//p[@class='no_today']/em/span""),1)"),15205) -> 15205 | L6: =$G6*K6 -> 99714390 | M6: =L6-$J6 -> 23917026 | N6: =(L6-$J6)/$J6 -> 0.31553902
D8: 한국 | E8: 0418J0 | F8: TIGER 휴머노이드로봇 | G8: 0 | H8: 14660 | J8: =G8*H8 -> 0 | K8: =IFERROR(__xludf.DUMMYFUNCTION("VALUE( SUBSTITUTE( IMPORTXML( ""https://finance.naver.com/item/main.naver?code=0148J0"", ""//p[@class='no_today']/em/span"" ), "","","""" ) )"),16275) -> 16275 | L8: =$G8*K8 -> 0 | M8: =L8-$J8 -> 0 | N8: =IFERROR(M8/(L8),) -> 0
D9: 한국
D10: 한국 | E10: 458730 | F10: 미국배당 다우존스 | G10: 8 | H10: 10805 | J10: =G10*H10 -> 86440 | K10: =IFERROR(__xludf.DUMMYFUNCTION("iferror(IF($D10=""한국"",GOOGLEFINANCE($E10),""""),)"),15405) -> 15405 | L10: =$G10*K10 -> 123240 | M10: =L10-$J10 -> 36800 | N10: =(L10-$J10)/$J10 -> 0.42572883
D11: 한국 | E11: 483280 | F11: Kodex AI Top TOP 커버드 | G11: 1 | H11: 11005 | J11: =G11*H11 -> 11005 | K11: =IFERROR(__xludf.DUMMYFUNCTION("iferror(IF($D11=""한국"",GOOGLEFINANCE($E11),""""),)"),13815) -> 13815 | L11: =$G11*K11 -> 13815 | M11: =L11-$J11 -> 2810 | N11: =(L11-$J11)/$J11 -> 0.25533848
B16: 합 계 | J16: =SUM(J5:J15) -> 281957211 | L16: =SUM(L5:L15) -> 335667170 | M16: =L16-C5 -> 221943066 | N16: =(L16-$C5)/$C5 -> 1.9515921
B17: 개인연금(기존) (220-34-xxxx-151) | C17: =IFERROR(__xludf.DUMMYFUNCTION("IMPORTRANGE(""18m7_5Vy-SocSuBMtXmritoiWfMy_VSJ0LqQCfdmFyYU/edit?gid=852545723"",""'1.자산투자(원금)'!q7"")"),16391196) -> 16391196 | D17: 한국 | E17: 442580 | F17: Plus HBM 글로벌 반도체 | G17: 586 | H17: 121729 | J17: =G17*H17 -> 71333194 | K17: =IFERROR(__xludf.DUMMYFUNCTION("iferror(IF($D17=""한국"",GOOGLEFINANCE($E17),""""),)"),127675) -> 127675 | L17: =$G17*K17 -> 74817550 | M17: =L17-$J17 -> 3484356 | N17: =(L17-$J17)/$J17 -> 0.048846208
D18: 한국 | E18: 0177R0 | F18: TIGER 반도체TOP10 커버드콜 | G18: 8 | H18: 12976 | J18: =G18*H18 -> 103808 | K18: =IFERROR(__xludf.DUMMYFUNCTION("INDEX(IMPORTXML(""https://finance.naver.com/item/main.naver?code=0177R0"",""//p[@class='no_today']/em/span""),1)"),15610) -> 15610 | L18: =$G18*K18 -> 124880 | M18: =L18-$J18 -> 21072 | N18: =(L18-$J18)/$J18 -> 0.20299014
D19: 한국 | E19: 458730 | F19: 미국배당 다우존스 | G19: 3 | H19: 10827 | J19: =G19*H19 -> 32481 | K19: =IFERROR(__xludf.DUMMYFUNCTION("iferror(IF($D19=""한국"",GOOGLEFINANCE($E19),""""),)"),15405) -> 15405 | L19: =$G19*K19 -> 46215 | M19: =L19-$J19 -> 13734 | N19: =(L19-$J19)/$J19 -> 0.42283181
D20: 한국 | E20: 0162Z0 | F20: RISE 삼성하이닉스채권 | G20: 1 | H20: 11005 | J20: =G20*H20 -> 11005 | K20: =IFERROR(__xludf.DUMMYFUNCTION("INDEX(IMPORTXML(""https://finance.naver.com/item/main.naver?code=0162Z0"",""//p[@class='no_today']/em/span""),1)"),15205) -> 15205 | L20: =$G20*K20 -> 15205 | M20: =L20-$J20 -> 4200 | N20: =(L20-$J20)/$J20 -> 0.38164471
B26: 합 계 | J26: =SUM(J17:J24) -> 71480488 | L26: =SUM(L17:L24) -> 75003850 | M26: =L26-C17 -> 58612654 | N26: =(L26-$C17)/$C17 -> 3.5758619
B27: 개인연금(신) (112-8680-xxxx-0) | C27: =IFERROR(__xludf.DUMMYFUNCTION("IMPORTRANGE(""18m7_5Vy-SocSuBMtXmritoiWfMy_VSJ0LqQCfdmFyYU/edit?gid=852545723"",""'1.자산투자(원금)'!q8"")"),14550000) -> 14550000 | D27: 한국 | E27: 442580 | F27: Plus HBM 글로벌 반도체 | G27: 302 | H27: 121080 | J27: =G27*H27 -> 36566160 | K27: =IFERROR(__xludf.DUMMYFUNCTION("iferror(IF($D27=""한국"",GOOGLEFINANCE($E27),""""),)"),127675) -> 127675 | L27: =$G27*K27 -> 38557850 | M27: =L27-$J27 -> 1991690 | N27: =(L27-$J27)/$J27 -> 0.05446812
D28: 한국 | E28: 0177R0 | F28: TIGER 반도체TOP10 커버드콜 | G28: 15 | H28: 12950 | J28: =G28*H28 -> 194250 | K28: =IFERROR(__xludf.DUMMYFUNCTION("INDEX(IMPORTXML(""https://finance.naver.com/item/main.naver?code=0177R0"",""//p[@class='no_today']/em/span""),1)"),15610) -> 15610 | L28: =$G28*K28 -> 234150 | M28: =L28-$J28 -> 39900 | N28: =(L28-$J28)/$J28 -> 0.20540541
D29: 한국 | E29: 458730 | F29: 미국배당 다우존스 | G29: 1 | H29: 10976 | J29: =G29*H29 -> 10976 | K29: =IFERROR(__xludf.DUMMYFUNCTION("iferror(IF($D29=""한국"",GOOGLEFINANCE($E29),""""),)"),15405) -> 15405 | L29: =$G29*K29 -> 15405 | M29: =L29-$J29 -> 4429 | N29: =(L29-$J29)/$J29 -> 0.40351676
D30: 한국 | E30: 490090 | F30: TIGER AI 빅테크 | G30: 1 | H30: 11266 | J30: =G30*H30 -> 11266 | K30: =IFERROR(__xludf.DUMMYFUNCTION("iferror(IF($D30=""한국"",GOOGLEFINANCE($E30),""""),)"),17805) -> 17805 | L30: =$G30*K30 -> 17805 | M30: =L30-$J30 -> 6539 | N30: =(L30-$J30)/$J30 -> 0.58041896
B35: 합 계 | J35: =SUM(J27:J34) -> 36782652 | L35: =SUM(L27:L34) -> 38825210 | M35: =L35-C27 -> 24275210 | N35: =(L35-$C27)/$C27 -> 1.6683993
B36: DC 계좌 (496-3028-xxx-0) | C36: =IFERROR(__xludf.DUMMYFUNCTION("IMPORTRANGE(""18m7_5Vy-SocSuBMtXmritoiWfMy_VSJ0LqQCfdmFyYU/edit?gid=852545723"",""'1.자산투자(원금)'!q9"")"),51504545) -> 51504545 | D36: 한국 | E36: 390390 | F36: 미국반도체 | G36: 0 | H36: 26431 | J36: =G36*H36 -> 0 | K36: =IFERROR(__xludf.DUMMYFUNCTION("iferror(IF($D36=""한국"",GOOGLEFINANCE($E36),""""),)"),63025) -> 63025 | L36: =$G36*K36 -> 0 | M36: =L36-$J36 -> 0 | N36: =(L36-$J36)/$J36 -> #DIV/0!
D37: 한국 | E37: 442580 | F37: Plus HBM 글로벌 반도체 | G37: 717 | H37: 111596 | J37: =G37*H37 -> 80014332 | K37: =IFERROR(__xludf.DUMMYFUNCTION("iferror(IF($D37=""한국"",GOOGLEFINANCE($E37),""""),)"),127675) -> 127675 | L37: =$G37*K37 -> 91542975 | M37: =L37-$J37 -> 11528643 | N37: =(L37-$J37)/$J37 -> 0.14408223
D38: 한국 | E38: 0162Z0 | F38: RISE 삼성하이닉스채권 | G38: 2547 | H38: 11534 | J38: =G38*H38 -> 29377098 | K38: =IFERROR(__xludf.DUMMYFUNCTION("INDEX(IMPORTXML(""https://finance.naver.com/item/main.naver?code=0162Z0"",""//p[@class='no_today']/em/span""),1)"),15205) -> 15205 | L38: =$G38*K38 -> 38727135 | M38: =L38-$J38 -> 9350037 | N38: =(L38-$J38)/$J38 -> 0.3182764
B42: 합 계 | J42: =SUM(J36:J40) -> 109391430 | L42: =SUM(L36:L40) -> 130270110 | M42: =L42-C36 -> 78765565 | N42: =(L42-$C36)/$C36 -> 1.5292935
B43: 퇴직연금(삼성) (648-8656-xxx) | C43: =IFERROR(__xludf.DUMMYFUNCTION("IMPORTRANGE(""18m7_5Vy-SocSuBMtXmritoiWfMy_VSJ0LqQCfdmFyYU/edit?gid=852545723"",""'1.자산투자(원금)'!q13"")"),2250000) -> 2250000 | D43: 한국 | E43: 390390 | F43: 미국반도체 | G43: 0 | H43: 33867 | J43: =G43*H43 -> 0 | K43: =IFERROR(__xludf.DUMMYFUNCTION("iferror(IF($D43=""한국"",GOOGLEFINANCE($E43),""""),)"),63025) -> 63025 | L43: =$G43*K43 -> 0 | M43: =L43-$J43 -> 0 | N43: =(L43-$J43)/$J43 -> #DIV/0!
D44: 한국 | E44: 396500 | F44: TIGER 반도체TOP10 | G44: 51 | H44: 31409 | J44: =G44*H44 -> 1601859 | K44: =IFERROR(__xludf.DUMMYFUNCTION("iferror(IF($D44=""한국"",GOOGLEFINANCE($E44),""""),)"),52085) -> 52085 | L44: =$G44*K44 -> 2656335 | M44: =L44-$J44 -> 1054476 | N44: =(L44-$J44)/$J44 -> 0.65828266
D45: 한국 | E45: 0162Z0 | F45: RISE 삼성하이닉스채권 | G45: 72 | H45: 11645 | J45: =G45*H45 -> 838440 | K45: =IFERROR(__xludf.DUMMYFUNCTION("INDEX(IMPORTXML(""https://finance.naver.com/item/main.naver?code=0162Z0"",""//p[@class='no_today']/em/span""),1)"),15205) -> 15205 | L45: =$G45*K45 -> 1094760 | M45: =L45-$J45 -> 256320 | N45: =(L45-$J45)/$J45 -> 0.30571061
D46: 한국 | E46: 411060 | F46: ACE KRX 금현물 | G46: 1 | H46: 29680 | J46: =G46*H46 -> 29680 | K46: =IFERROR(__xludf.DUMMYFUNCTION("iferror(IF($D46=""한국"",GOOGLEFINANCE($E46),""""),)"),30175) -> 30175 | L46: =$G46*K46 -> 30175 | M46: =L46-$J46 -> 495 | N46: =(L46-$J46)/$J46 -> 0.016677898
D47: 한국 | E47: 251600 | F47: Plus 고배당주 채권혼합 | G47: 1 | H47: 14120 | J47: =G47*H47 -> 14120 | K47: =IFERROR(__xludf.DUMMYFUNCTION("iferror(IF($D47=""한국"",GOOGLEFINANCE($E47),""""),)"),15760) -> 15760 | L47: =$G47*K47 -> 15760 | M47: =L47-$J47 -> 1640 | N47: =(L47-$J47)/$J47 -> 0.11614731
B53: 합 계 | J53: =SUM(J43:J52) -> 2484099 | L53: =SUM(L43:L52) -> 3797030 | M53: =L53-C43 -> 1547030 | N53: =(L53-C43)/C43 -> 0.68756889
B54: 연금(합계) | C54: =SUM(C5:C47) -> 198419845 | J54: =J16+J26+J35+J42+J53 -> 502095880 | L54: =L16+L26+L35+L42+L53 -> 583563370 | M54: =L54-C54 -> 385143525 | N54: =(L54-C54)/C54 -> 1.9410535
B55: 처리 투자 (미래에셋) | C55: =IFERROR(__xludf.DUMMYFUNCTION("IMPORTRANGE(""18m7_5Vy-SocSuBMtXmritoiWfMy_VSJ0LqQCfdmFyYU/edit?gid=852545723"",""'1.자산투자(원금)'!q14"")"),16441657) -> 16441657 | D55: 한국 | E55: 396500 | F55: TIGER 반도체 TOP10 | G55: 569 | H55: 30933 | J55: =G55*H55 -> 17600877 | K55: =IFERROR(__xludf.DUMMYFUNCTION("iferror(IF($D55=""한국"",GOOGLEFINANCE($E55),""""),)"),52085) -> 52085 | L55: =$G55*K55 -> 29636365 | M55: =L55-$J55 -> 12035488 | N55: =(L55-$J55)/$J55 -> 0.68380047
D56: 한국 | E56: 442580 | F56: Plus HBM 글로벌 반도체 | G56: 405 | H56: 124907 | J56: =G56*H56 -> 50587335 | K56: =IFERROR(__xludf.DUMMYFUNCTION("iferror(IF($D56=""한국"",GOOGLEFINANCE($E56),""""),)"),127675) -> 127675 | L56: =$G56*K56 -> 51708375 | M56: =L56-$J56 -> 1121040 | N56: =(L56-$J56)/$J56 -> 0.022160487
D57: 한국 | E57: 395160 | F57: KODEX AI 반도체 TOP2 | J57: =G57*H57 -> 0 | K57: =IFERROR(__xludf.DUMMYFUNCTION("iferror(IF($D57=""한국"",GOOGLEFINANCE($E57),""""),)"),52000) -> 52000 | L57: =$G57*K57 -> 0 | M57: =L57-$J57 -> 0 | N57: =(L57-$J57)/$J57 -> #DIV/0!
D58: 한국 | E58: 0162Z0 | F58: RISE 삼성하이닉스채권 | G58: 2 | H58: 13474 | J58: =G58*H58 -> 26948 | K58: =IFERROR(__xludf.DUMMYFUNCTION("INDEX(IMPORTXML(""https://finance.naver.com/item/main.naver?code=0162Z0"",""//p[@class='no_today']/em/span""),1)"),15205) -> 15205 | L58: =$G58*K58 -> 30410 | M58: =L58-$J58 -> 3462 | N58: =(L58-$J58)/$J58 -> 0.12846965
D59: 한국 | E59: 480020 | F59: ACE 빅테크7 커버드콜 | G59: 2 | H59: 10332 | J59: =G59*H59 -> 20664 | K59: =IFERROR(__xludf.DUMMYFUNCTION("iferror(IF($D59=""한국"",GOOGLEFINANCE($E59),""""),)"),13885) -> 13885 | L59: =$G59*K59 -> 27770 | M59: =L59-$J59 -> 7106 | N59: =(L59-$J59)/$J59 -> 0.34388308
D60: 한국 | E60: 0195R0 | F60: TIGER 삼성전자 레버리지 | G60: 3 | H60: 27558 | J60: =G60*H60 -> 82674 | K60: =IFERROR(__xludf.DUMMYFUNCTION("INDEX(IMPORTXML(""https://finance.naver.com/item/main.naver?code=0195R0"",""//p[@class='no_today']/em/span""),1)"),28950) -> 28950 | L60: =$G60*K60 -> 86850 | M60: =L60-$J60 -> 4176 | N60: =(L60-$J60)/$J60 -> 0.050511648
B61: 합 계 | J61: =SUM(J55:J59) -> 68235824 | L61: =SUM(L55:L59) -> 81402920 | M61: =L61-C55 -> 64961263 | N61: =(L61-$C55)/$C55 -> 3.9510168
J62: =G62*H62 -> 0 | K62: =IFERROR(__xludf.DUMMYFUNCTION("iferror(IF($D62=""한국"",GOOGLEFINANCE($E62),""""),)"),"") | L62: =$G62*K62 -> #VALUE! | M62: =L62-$J62 -> #VALUE! | N62: =(L62-$J62)/$J62 -> #VALUE!
B63: 합 계 | J63: =SUM(J62) -> 0 | L63: =SUM(L62) -> #VALUE! | M63: =L63-$J63 -> #VALUE! | N63: =(L63-$J63)/$J63 -> #VALUE!
B64: 처리 투자 (삼성증권) | C64: =IFERROR(__xludf.DUMMYFUNCTION("IMPORTRANGE(""18m7_5Vy-SocSuBMtXmritoiWfMy_VSJ0LqQCfdmFyYU/edit?gid=852545723"",""'1.자산투자(원금)'!q11"")"),0) -> 0 | D64: 미국 | E64: NVDA | F64: 엔비디아 | G64: 0 | H64: 120 | J64: =IFERROR(__xludf.DUMMYFUNCTION("G64*H64*GOOGLEFINANCE(""usdkrw"")"),0) -> 0 | K64: =IFERROR(__xludf.DUMMYFUNCTION("iferror(IF($D64=""미국"",GOOGLEFINANCE($E64),""""),)"),222.82) -> 222.82 | L64: =IFERROR(__xludf.DUMMYFUNCTION("G64*GOOGLEFINANCE(""usdkrw"")*K64"),0) -> 0 | M64: =L64-$J64 -> 0 | N64: =(L64-$J64)/$J64 -> #DIV/0!
...

Sheet 2,현재 실적
B1: 투자 원금 | C1: 투자 종목 코드 | D1: 투자 종목 명칭 | E1: 수량 | F1: 투자 단가 | G1: 과세 표준가 | H1: 현재가 | I1: 현재 금액 | J1: 수익율
A2: 퇴직연금 (220-91-xxxx-757) | B2: ='1. 투자 현황(현재)'!C5 -> 113724104 | C2: ='1. 투자 현황(현재)'!E5 -> 442580 | D2: ='1. 투자 현황(현재)'!F5 -> Plus HBM 글로벌 반도체 | E2: ='1. 투자 현황(현재)'!G5 -> 1847 | F2: ='1. 투자 현황(현재)'!H5 -> 111566 | G2: 61209.27 | H2: ='1. 투자 현황(현재)'!K5 -> 127675 | I2: ='1. 투자 현황(현재)'!L5 -> 235815725 | J2: ='1. 투자 현황(현재)'!N5 -> 0.14438987
C3: ='1. 투자 현황(현재)'!E6 -> 0162Z0 | D3: ='1. 투자 현황(현재)'!F6 -> RISE 삼성하이닉스채권 | E3: ='1. 투자 현황(현재)'!G6 -> 6558 | F3: ='1. 투자 현황(현재)'!H6 -> 11558 | H3: ='1. 투자 현황(현재)'!K6 -> 15205 | I3: ='1. 투자 현황(현재)'!L6 -> 99714390 | J3: ='1. 투자 현황(현재)'!N6 -> 0.31553902
C4: ='1. 투자 현황(현재)'!E10 -> 458730 | D4: ='1. 투자 현황(현재)'!F10 -> 미국배당 다우존스 | E4: ='1. 투자 현황(현재)'!G10 -> 8 | F4: ='1. 투자 현황(현재)'!H10 -> 10805 | H4: ='1. 투자 현황(현재)'!K10 -> 15405 | I4: ='1. 투자 현황(현재)'!L10 -> 123240 | J4: ='1. 투자 현황(현재)'!N10 -> 0.42572883
C5: ='1. 투자 현황(현재)'!E11 -> 483280 | D5: ='1. 투자 현황(현재)'!F11 -> Kodex AI Top TOP 커버드 | E5: ='1. 투자 현황(현재)'!G11 -> 1 | F5: ='1. 투자 현황(현재)'!H11 -> 11005 | H5: ='1. 투자 현황(현재)'!K11 -> 13815 | I5: ='1. 투자 현황(현재)'!L11 -> 13815 | J5: ='1. 투자 현황(현재)'!N11 -> 0.25533848
A6: 소계 | I6: =SUM(I2:I5) -> 335667170 | J6: =(I6-B2)/B2 -> 1.9515921
A7: 개인연금(기존) (220-34-xxxx-151) | B7: ='1. 투자 현황(현재)'!C17 -> 16391196 | C7: ='1. 투자 현황(현재)'!E17 -> 442580 | D7: ='1. 투자 현황(현재)'!F17 -> Plus HBM 글로벌 반도체 | E7: ='1. 투자 현황(현재)'!G17 -> 586 | F7: ='1. 투자 현황(현재)'!H17 -> 121729 | G7: 61209.27 | H7: ='1. 투자 현황(현재)'!K17 -> 127675 | I7: ='1. 투자 현황(현재)'!L17 -> 74817550 | J7: ='1. 투자 현황(현재)'!N17 -> 0.048846208
C8: ='1. 투자 현황(현재)'!E18 -> 0177R0 | D8: ='1. 투자 현황(현재)'!F18 -> TIGER 반도체TOP10 커버드콜 | E8: ='1. 투자 현황(현재)'!G18 -> 8 | F8: ='1. 투자 현황(현재)'!H18 -> 12976 | H8: ='1. 투자 현황(현재)'!K18 -> 15610 | I8: ='1. 투자 현황(현재)'!L18 -> 124880 | J8: ='1. 투자 현황(현재)'!N18 -> 0.20299014
C9: ='1. 투자 현황(현재)'!E19 -> 458730 | D9: ='1. 투자 현황(현재)'!F19 -> 미국배당 다우존스 | E9: ='1. 투자 현황(현재)'!G19 -> 3 | F9: ='1. 투자 현황(현재)'!H19 -> 10827 | H9: ='1. 투자 현황(현재)'!K19 -> 15405 | I9: ='1. 투자 현황(현재)'!L19 -> 46215 | J9: ='1. 투자 현황(현재)'!N19 -> 0.42283181
C10: ='1. 투자 현황(현재)'!E20 -> 0162Z0 | D10: ='1. 투자 현황(현재)'!F20 -> RISE 삼성하이닉스채권 | E10: ='1. 투자 현황(현재)'!G20 -> 1 | F10: ='1. 투자 현황(현재)'!H20 -> 11005 | H10: ='1. 투자 현황(현재)'!K20 -> 15205 | I10: ='1. 투자 현황(현재)'!L20 -> 15205 | J10: ='1. 투자 현황(현재)'!N20 -> 0.38164471
A11: 소계 | I11: =SUM(I7:I10) -> 75003850 | J11: =(I11-B7)/B7 -> 3.5758619
A12: 개인연금(신) (112-8680-xxxx-0) | B12: ='1. 투자 현황(현재)'!C27 -> 14550000 | C12: ='1. 투자 현황(현재)'!E27 -> 442580 | D12: ='1. 투자 현황(현재)'!F27 -> Plus HBM 글로벌 반도체 | E12: ='1. 투자 현황(현재)'!G27 -> 302 | F12: ='1. 투자 현황(현재)'!H27 -> 121080 | G12: 61209.27 | H12: ='1. 투자 현황(현재)'!K27 -> 127675 | I12: ='1. 투자 현황(현재)'!L27 -> 38557850 | J12: ='1. 투자 현황(현재)'!N27 -> 0.05446812
C13: ='1. 투자 현황(현재)'!E28 -> 0177R0 | D13: ='1. 투자 현황(현재)'!F28 -> TIGER 반도체TOP10 커버드콜 | E13: ='1. 투자 현황(현재)'!G28 -> 15 | F13: ='1. 투자 현황(현재)'!H28 -> 12950 | H13: ='1. 투자 현황(현재)'!K28 -> 15610 | I13: ='1. 투자 현황(현재)'!L28 -> 234150 | J13: ='1. 투자 현황(현재)'!N28 -> 0.20540541
C14: ='1. 투자 현황(현재)'!E29 -> 458730 | D14: ='1. 투자 현황(현재)'!F29 -> 미국배당 다우존스 | E14: ='1. 투자 현황(현재)'!G29 -> 1 | F14: ='1. 투자 현황(현재)'!H29 -> 10976 | H14: ='1. 투자 현황(현재)'!K29 -> 15405 | I14: ='1. 투자 현황(현재)'!L29 -> 15405 | J14: ='1. 투자 현황(현재)'!N29 -> 0.40351676
C15: ='1. 투자 현황(현재)'!E30 -> 490090 | D15: ='1. 투자 현황(현재)'!F30 -> TIGER AI 빅테크 | E15: ='1. 투자 현황(현재)'!G30 -> 1 | F15: ='1. 투자 현황(현재)'!H30 -> 11266 | H15: ='1. 투자 현황(현재)'!K30 -> 17805 | I15: ='1. 투자 현황(현재)'!L30 -> 17805 | J15: ='1. 투자 현황(현재)'!N30 -> 0.58041896
A16: 소계 | I16: =SUM(I12:I15) -> 38825210 | J16: =(I16-B12)/B12 -> 1.6683993
A17: DC 계좌 (496-3028-xxx-0) | B17: ='1. 투자 현황(현재)'!C36 -> 51504545 | C17: ='1. 투자 현황(현재)'!E37 -> 442580 | D17: ='1. 투자 현황(현재)'!F37 -> Plus HBM 글로벌 반도체 | E17: ='1. 투자 현황(현재)'!G37 -> 717 | F17: ='1. 투자 현황(현재)'!H37 -> 111596 | G17: 61209.27 | H17: ='1. 투자 현황(현재)'!K37 -> 127675 | I17: ='1. 투자 현황(현재)'!L37 -> 91542975 | J17: ='1. 투자 현황(현재)'!N37 -> 0.14408223
B18: ='1. 투자 현황(현재)'!C36 -> 51504545 | C18: ='1. 투자 현황(현재)'!E38 -> 0162Z0 | D18: ='1. 투자 현황(현재)'!F38 -> RISE 삼성하이닉스채권 | E18: ='1. 투자 현황(현재)'!G38 -> 2547 | F18: ='1. 투자 현황(현재)'!H38 -> 11534 | H18: ='1. 투자 현황(현재)'!K38 -> 15205 | I18: ='1. 투자 현황(현재)'!L38 -> 38727135 | J18: ='1. 투자 현황(현재)'!N38 -> 0.3182764
A19: 소계 | I19: =SUM(I17:I18) -> 130270110 | J19: =(I19-B17)/B17 -> 1.5292935
A20: 퇴직연금(삼성) (648-8656-xxx) | B20: ='1. 투자 현황(현재)'!C43 -> 2250000 | C20: ='1. 투자 현황(현재)'!E44 -> 396500 | D20: ='1. 투자 현황(현재)'!F44 -> TIGER 반도체TOP10 | E20: ='1. 투자 현황(현재)'!G44 -> 51 | F20: ='1. 투자 현황(현재)'!H44 -> 31409 | H20: ='1. 투자 현황(현재)'!K44 -> 52085 | I20: ='1. 투자 현황(현재)'!L44 -> 2656335 | J20: ='1. 투자 현황(현재)'!N44 -> 0.65828266
B21: ='1. 투자 현황(현재)'!C43 -> 2250000 | C21: ='1. 투자 현황(현재)'!E45 -> 0162Z0 | D21: ='1. 투자 현황(현재)'!F45 -> RISE 삼성하이닉스채권 | E21: ='1. 투자 현황(현재)'!G45 -> 72 | F21: ='1. 투자 현황(현재)'!H45 -> 11645 | H21: ='1. 투자 현황(현재)'!K45 -> 15205 | I21: ='1. 투자 현황(현재)'!L45 -> 1094760 | J21: ='1. 투자 현황(현재)'!N45 -> 0.30571061
B22: ='1. 투자 현황(현재)'!C43 -> 2250000 | C22: ='1. 투자 현황(현재)'!E46 -> 411060 | D22: ='1. 투자 현황(현재)'!F46 -> ACE KRX 금현물 | E22: ='1. 투자 현황(현재)'!G46 -> 1 | F22: ='1. 투자 현황(현재)'!H46 -> 29680 | H22: ='1. 투자 현황(현재)'!K46 -> 30175 | I22: ='1. 투자 현황(현재)'!L46 -> 30175 | J22: ='1. 투자 현황(현재)'!N46 -> 0.016677898
B23: ='1. 투자 현황(현재)'!C43 -> 2250000 | C23: ='1. 투자 현황(현재)'!E47 -> 251600 | D23: ='1. 투자 현황(현재)'!F47 -> Plus 고배당주 채권혼합 | E23: ='1. 투자 현황(현재)'!G47 -> 1 | F23: ='1. 투자 현황(현재)'!H47 -> 14120 | H23: ='1. 투자 현황(현재)'!K47 -> 15760 | I23: ='1. 투자 현황(현재)'!L47 -> 15760 | J23: ='1. 투자 현황(현재)'!N47 -> 0.11614731
A24: 소계 | I24: =SUM(I20:I23) -> 3797030 | J24: =(I24-B20)/B20 -> 0.68756889
A25: 연금 합계 | B25: ='1. 투자 현황(현재)'!C54 -> 198419845 | I25: ='1. 투자 현황(현재)'!L54 -> 583563370 | J25: ='1. 투자 현황(현재)'!N54 -> 1.9410535
A26: 처리투자(미래에셋) | B26: ='1. 투자 현황(현재)'!C55 -> 16441657 | C26: ='1. 투자 현황(현재)'!E55 -> 396500 | D26: ='1. 투자 현황(현재)'!F55 -> TIGER 반도체 TOP10 | E26: ='1. 투자 현황(현재)'!G55 -> 569 | F26: ='1. 투자 현황(현재)'!H55 -> 30933 | H26: ='1. 투자 현황(현재)'!K55 -> 52085 | I26: ='1. 투자 현황(현재)'!L55 -> 29636365 | J26: ='1. 투자 현황(현재)'!N55 -> 0.68380047
B27: ='1. 투자 현황(현재)'!C55 -> 16441657 | C27: ='1. 투자 현황(현재)'!E56 -> 442580 | D27: ='1. 투자 현황(현재)'!F56 -> Plus HBM 글로벌 반도체 | E27: ='1. 투자 현황(현재)'!G56 -> 405 | F27: ='1. 투자 현황(현재)'!H56 -> 124907 | G27: 61209.27 | H27: ='1. 투자 현황(현재)'!K56 -> 127675 | I27: ='1. 투자 현황(현재)'!L56 -> 51708375 | J27: ='1. 투자 현황(현재)'!N56 -> 0.022160487
B28: ='1. 투자 현황(현재)'!C55 -> 16441657 | C28: ='1. 투자 현황(현재)'!E58 -> 0162Z0 | D28: ='1. 투자 현황(현재)'!F58 -> RISE 삼성하이닉스채권 | E28: ='1. 투자 현황(현재)'!G58 -> 2 | F28: ='1. 투자 현황(현재)'!H58 -> 13474 | H28: ='1. 투자 현황(현재)'!K58 -> 15205 | I28: ='1. 투자 현황(현재)'!L58 -> 30410 | J28: ='1. 투자 현황(현재)'!N58 -> 0.12846965
B29: ='1. 투자 현황(현재)'!C55 -> 16441657 | C29: ='1. 투자 현황(현재)'!E59 -> 480020 | D29: ='1. 투자 현황(현재)'!F59 -> ACE 빅테크7 커버드콜 | E29: ='1. 투자 현황(현재)'!G59 -> 2 | F29: ='1. 투자 현황(현재)'!H59 -> 10332 | H29: ='1. 투자 현황(현재)'!K59 -> 13885 | I29: ='1. 투자 현황(현재)'!L59 -> 27770 | J29: ='1. 투자 현황(현재)'!N59 -> 0.34388308
B30: ='1. 투자 현황(현재)'!C55 -> 16441657 | C30: ='1. 투자 현황(현재)'!E60 -> 0195R0 | D30: ='1. 투자 현황(현재)'!F60 -> TIGER 삼성전자 레버리지 | E30: ='1. 투자 현황(현재)'!G60 -> 3 | F30: ='1. 투자 현황(현재)'!H60 -> 27558 | H30: ='1. 투자 현황(현재)'!K60 -> 28950 | I30: ='1. 투자 현황(현재)'!L60 -> 86850 | J30: ='1. 투자 현황(현재)'!N60 -> 0.050511648
A31: 소계 | I31: =SUM(I26:I30) -> 81489770 | J31: =(I31-B26)/B26 -> 3.9562991
A32: 은퇴투자(삼성증권) | B32: ='1. 투자 현황(현재)'!C71 -> 0 | C32: ='1. 투자 현황(현재)'!E71 -> STX | D32: ='1. 투자 현황(현재)'!F71 -> 시게이트 | E32: ='1. 투자 현황(현재)'!G71 -> 0.1 | F32: ='1. 투자 현황(현재)'!H71 -> 317.56 | H32: ='1. 투자 현황(현재)'!K71 -> 926.61 | I32: ='1. 투자 현황(현재)'!L71 -> 142194.33 | J32: ='1. 투자 현황(현재)'!N71 -> 1.9179053
A33: 소계 | I33: =SUM(I32) -> 142194.33 | J33: ='1. 투자 현황(현재)'!N71 -> 1.9179053
A34: 은퇴투자(미래에셋) | B34: ='1. 투자 현황(현재)'!C81 -> 118653718 | C34: ='1. 투자 현황(현재)'!E81 -> 396500 | D34: ='1. 투자 현황(현재)'!F81 -> TIGER 반도체TOP10 | E34: ='1. 투자 현황(현재)'!G81 -> 2059 | F34: ='1. 투자 현황(현재)'!H81 -> 31800 | H34: ='1. 투자 현황(현재)'!K81 -> 52085 | I34: ='1. 투자 현황(현재)'!L81 -> 107243015 | J34: ='1. 투자 현황(현재)'!N81 -> 0.63789308
B35: ='1. 투자 현황(현재)'!C81 -> 118653718 | C35: ='1. 투자 현황(현재)'!E82 -> 442580 | D35: ='1. 투자 현황(현재)'!F82 -> Plus HBM 글로벌 반도체 | E35: ='1. 투자 현황(현재)'!G82 -> 1275 | F35: ='1. 투자 현황(현재)'!H82 -> 124747 | G35: 61209.27 | H35: ='1. 투자 현황(현재)'!K82 -> 127675 | I35: ='1. 투자 현황(현재)'!L82 -> 162785625 | J35: ='1. 투자 현황(현재)'!N82 -> 0.023471506
B36: ='1. 투자 현황(현재)'!C81 -> 118653718 | C36: ='1. 투자 현황(현재)'!E83 -> 0195R0 | D36: ='1. 투자 현황(현재)'!F83 -> TIGER 삼성전자 레버리지 | E36: ='1. 투자 현황(현재)'!G83 -> 1031 | F36: ='1. 투자 현황(현재)'!H83 -> 22973 | H36: ='1. 투자 현황(현재)'!K83 -> 28950 | I36: ='1. 투자 현황(현재)'!L83 -> 29847450 | J36: ='1. 투자 현황(현재)'!N83 -> 0.26017499
B37: ='1. 투자 현황(현재)'!C81 -> 118653718 | C37: ='1. 투자 현황(현재)'!E85 -> 390390 | D37: ='1. 투자 현황(현재)'!F85 -> KODEX 미국 반도체 | E37: ='1. 투자 현황(현재)'!G85 -> 3 | F37: ='1. 투자 현황(현재)'!H85 -> 19187 | H37: ='1. 투자 현황(현재)'!K85 -> 63025 | I37: ='1. 투자 현황(현재)'!L85 -> 189075 | J37: ='1. 투자 현황(현재)'!N85 -> 2.2847762
B38: ='1. 투자 현황(현재)'!C81 -> 118653718 | C38: ='1. 투자 현황(현재)'!E86 -> 0177R0 | D38: ='1. 투자 현황(현재)'!F86 -> TIGER 반도체TOP10 커버드콜 | E38: ='1. 투자 현황(현재)'!G86 -> 4 | F38: ='1. 투자 현황(현재)'!H86 -> 12960 | H38: ='1. 투자 현황(현재)'!K86 -> 15610 | I38: ='1. 투자 현황(현재)'!L86 -> 62440 | J38: ='1. 투자 현황(현재)'!N86 -> 0.20447531
B39: ='1. 투자 현황(현재)'!C81 -> 118653718 | C39: ='1. 투자 현황(현재)'!E87 -> 0162Z0 | D39: ='1. 투자 현황(현재)'!F87 -> RISE 삼성하이닉스채권 | E39: ='1. 투자 현황(현재)'!G87 -> 2 | F39: ='1. 투자 현황(현재)'!H87 -> 13471 | H39: ='1. 투자 현황(현재)'!K87 -> 15205 | I39: ='1. 투자 현황(현재)'!L87 -> 30410 | J39: ='1. 투자 현황(현재)'!N87 -> 0.12872096
A40: 소계 | I40: =SUM(I34:I39) -> 300158015 | J40: =(I40-B34)/B34 -> 1.5296975
...

Sheet 3.투자 실적(월별)
A1: 투자 실적 (월별)
A3: 계좌 | B3: 항목 | C3: 46143 | D3: 2026-06 | E3: 46204
A4: 퇴직연금(220-91) | B4: 투자원금 | C4: 113724104 | D4: ='2,현재 실적'!B2 -> 113724104
B5: 현재금액 | C5: 335667170 | D5: ='2,현재 실적'!I6 -> 335667170
B6: 수익금액 | C6: 221943066 | D6: ='2,현재 실적'!I6-'2,현재 실적'!B2 -> 221943066
B7: 수익률 | C7: 1.9515921 | D7: ='2,현재 실적'!J6 -> 1.9515921
A8: 개인연금(기존) | B8: 투자원금 | C8: 16391196 | D8: ='2,현재 실적'!B7 -> 16391196
B9: 현재금액 | C9: 75003850 | D9: ='2,현재 실적'!I11 -> 75003850
B10: 수익금액 | C10: 58612654 | D10: ='2,현재 실적'!I11-'2,현재 실적'!B7 -> 58612654
B11: 수익률 | C11: 3.5758619 | D11: ='2,현재 실적'!J11 -> 3.5758619
A12: 개인연금(신) | B12: 투자원금 | C12: 14550000 | D12: ='2,현재 실적'!B12 -> 14550000
B13: 현재금액 | C13: 38825210 | D13: ='2,현재 실적'!I16 -> 38825210
B14: 수익금액 | C14: 24275210 | D14: ='2,현재 실적'!I16-'2,현재 실적'!B12 -> 24275210
B15: 수익률 | C15: 1.6683993 | D15: ='2,현재 실적'!J16 -> 1.6683993
A16: DC계좌 | B16: 투자원금 | C16: 51504545 | D16: ='2,현재 실적'!B17 -> 51504545
B17: 현재금액 | C17: 130270110 | D17: ='2,현재 실적'!I19 -> 130270110
B18: 수익금액 | C18: 78765565 | D18: ='2,현재 실적'!I19-'2,현재 실적'!B17 -> 78765565
B19: 수익률 | C19: 1.5292935 | D19: ='2,현재 실적'!J19 -> 1.5292935
A20: 퇴직연금(삼성) | B20: 투자원금 | C20: 2250000 | D20: ='2,현재 실적'!B20 -> 2250000
B21: 현재금액 | C21: 3797030 | D21: ='2,현재 실적'!I24 -> 3797030
B22: 수익금액 | C22: 1547030 | D22: ='2,현재 실적'!I24-'2,현재 실적'!B20 -> 1547030
B23: 수익률 | C23: 0.68756889 | D23: ='2,현재 실적'!J24 -> 0.68756889
A24: 연금 합계 | B24: 투자원금 | C24: 198419845 | D24: ='2,현재 실적'!B25 -> 198419845
B25: 현재금액 | C25: 583563370 | D25: ='2,현재 실적'!I25 -> 583563370
B26: 수익금액 | C26: 385143525 | D26: ='2,현재 실적'!I25-'2,현재 실적'!B25 -> 385143525
B27: 수익률 | C27: 1.9410535 | D27: ='2,현재 실적'!J25 -> 1.9410535
A28: 처리투자(미래에셋) | B28: 투자원금 | C28: 16441657 | D28: ='2,현재 실적'!B26 -> 16441657
B29: 현재금액 | C29: 81489770 | D29: ='2,현재 실적'!I31 -> 81489770
B30: 수익금액 | C30: 65048113 | D30: ='2,현재 실적'!I31-'2,현재 실적'!B26 -> 65048113
B31: 수익률 | C31: 3.9562991 | D31: ='2,현재 실적'!J31 -> 3.9562991
A32: 은퇴투자(삼성증권) | B32: 투자원금 | C32: 0 | D32: ='2,현재 실적'!B32 -> 0
B33: 현재금액 | C33: 142194.33 | D33: ='2,현재 실적'!I33 -> 142194.33
B34: 수익금액 | C34: 142194.33 | D34: ='2,현재 실적'!I33-'2,현재 실적'!B32 -> 142194.33
B35: 수익률 | C35: 1.9179053 | D35: ='2,현재 실적'!J33 -> 1.9179053
A36: 은퇴투자(미래에셋) | B36: 투자원금 | C36: 118653718 | D36: ='2,현재 실적'!B34 -> 118653718
B37: 현재금액 | C37: 300158015 | D37: ='2,현재 실적'!I40 -> 300158015
B38: 수익금액 | C38: 181504297 | D38: ='2,현재 실적'!I40-'2,현재 실적'!B34 -> 181504297
B39: 수익률 | C39: 1.5296975 | D39: ='2,현재 실적'!J40 -> 1.5296975
A40: ISA 계좌 | B40: 투자원금 | C40: 500000 | D40: ='2,현재 실적'!B41 -> 500000
B41: 현재금액 | C41: 1890465 | D41: ='2,현재 실적'!I43 -> 1890465
...
